<?xml version="1.0"?>
<robot name="Master_Arm">

  <link name="world"/>

  <!-- Link Base -->
  <link name="MA_Base">
    <inertial>
      <mass value="0.66142136"/>
      <origin rpy="0 0 0" xyz="-0.01624256 0.00000000 -0.0111219"/>
      <inertia ixx="0.00454612" ixy="0.00000000" ixz="-0.00000412" iyy="0.00051668" iyz="-0.00000000" izz="0.00477987"/>
    </inertial>

    <visual>
    <origin xyz="0.0 0.0 0.010"/>
      <geometry>
        <mesh scale="0.001 0.001 0.001" filename="package://master_arm_display_pkg/urdf/meshes/MA_Base.stl"/>
      </geometry>
      <material name="LightGrey">
        <color rgba="0.7 0.7 0.7 1.0"/>
      </material>
    </visual>
  </link>

  <!-- Links_R -->
  <link name="MA_Link_J1R">
    <inertial>
      <mass value="0.22285683"/>
      <origin rpy="0 0 0" xyz="0.00048276 0.00994955 0.01143937"/>
      <inertia ixx="0.00010926" ixy="0.00000074" ixz="-0.00000050" iyy="0.00010180" iyz="0.00000089" izz="0.00008352"/>
    </inertial>

    <visual>
      <geometry>
        <mesh scale="0.001 0.001 0.001" filename="package://master_arm_display_pkg/urdf/meshes/MA_Link_J1R.stl"/>
      </geometry>
      <material name="LightGrey">
        <color rgba="0.7 0.7 0.7 1.0"/>
      </material>
    </visual>
  </link>


    <link name="MA_Link_J2R">
    <inertial>
      <mass value="0.24640382"/>
      <origin rpy="0 0 0" xyz="0.01296806 -0.00003277 -0.06516183"/>
      <inertia ixx="0.00013620" ixy="-0.00000010" ixz="0.00002637" iyy="0.00018743" iyz="0.00000055" izz="0.00011718"/>
    </inertial>

    <visual>
      <geometry>
        <mesh scale="0.001 0.001 0.001" filename="package://master_arm_display_pkg/urdf/meshes/MA_Link_J2R.stl"/>
      </geometry>
      <material name="LightGrey">
        <color rgba="0.7 0.7 0.7 1.0"/>
      </material>
    </visual>
  </link>


    <link name="MA_Link_J3R">
    <inertial>
      <mass value="0.21684531"/>
      <origin rpy="0 0 0" xyz="0.00870034 0.00016568 -0.18768815"/>
      <inertia ixx="0.00051472" ixy="-0.00000024" ixz="0.00008542" iyy="0.00054840" iyz="0.00000157" izz="0.00007709"/>
    </inertial>

    <visual>
      <geometry>
        <mesh scale="0.001 0.001 0.001" filename="package://master_arm_display_pkg/urdf/meshes/MA_Link_J3R.stl"/>
      </geometry>
      <material name="LightGrey">
        <color rgba="0.7 0.7 0.7 1.0"/>
      </material>
    </visual>
  </link>


    <link name="MA_Link_J4R">
    <inertial>
      <mass value="0.15321181"/>
      <origin rpy="0 0 0" xyz="-0.02116670 -0.00005817 -0.04223570"/>
      <inertia ixx="0.00005793" ixy="-0.00000015" ixz="-0.00000104" iyy="0.00006184" iyz="0.00000004" izz="0.00005738"/>
    </inertial>

    <visual>
      <geometry>
        <mesh scale="0.001 0.001 0.001" filename="package://master_arm_display_pkg/urdf/meshes/MA_Link_J4R.stl"/>
      </geometry>
      <material name="LightGrey">
        <color rgba="0.7 0.7 0.7 1.0"/>
      </material>
    </visual>
  </link>


    <link name="MA_Link_J5R">
    <inertial>
      <mass value="0.26207359"/>
      <origin rpy="0 0 0" xyz="0.00557790 0.00467349 0.08575803"/>
      <inertia ixx="0.00058849" ixy="0.00000738" ixz="0.00004243" iyy="0.00060743" iyz="0.00005519" izz="0.00011298"/>
    </inertial>

    <visual>
      <geometry>
        <mesh scale="0.001 0.001 0.001" filename="package://master_arm_display_pkg/urdf/meshes/MA_Link_J5R.stl"/>
      </geometry>
      <material name="LightGrey">
        <color rgba="0.7 0.7 0.7 1.0"/>
      </material>
    </visual>
  </link>


    <link name="MA_Link_J6R">
    <inertial>
      <mass value="0.12931104"/>
      <origin rpy="0 0 0" xyz="0.08132607 0.08060599 -0.05823234"/>
      <inertia ixx="0.00057977" ixy="-0.00012522" ixz="0.00006868" iyy="0.00071017" iyz="0.00023495" izz="0.00058411"/>
    </inertial>

    <visual>
      <geometry>
        <mesh scale="0.001 0.001 0.001" filename="package://master_arm_display_pkg/urdf/meshes/MA_Link_J6R.stl"/>
      </geometry>
      <material name="LightGrey">
        <color rgba="0.7 0.7 0.7 1.0"/>
      </material>
    </visual>
  </link>


    <link name="MA_Link_J7R">
    <inertial>
      <mass value="0.30239425"/>
      <origin rpy="0 0 0" xyz="0.02315134 0.00001279 -0.08248957"/>
      <inertia ixx="0.00022759" ixy="0.00000089" ixz="0.00003619" iyy="0.00064028" iyz="0.00000001" izz="0.00063638"/>
    </inertial>

    <visual>
      <geometry>
        <mesh scale="0.001 0.001 0.001" filename="package://master_arm_display_pkg/urdf/meshes/MA_Link_J7R.stl"/>
      </geometry>
      <material name="LightGrey">
        <color rgba="0.7 0.7 0.7 1.0"/>
      </material>
    </visual>
  </link>




 
  <!-- Links_L -->
      <link name="MA_Link_J1L">
    <inertial>
      <mass value="0.22285683"/>
      <origin rpy="0 0 0" xyz="0.00048276 -0.00994955 0.01143937"/>
      <inertia ixx="0.00010926" ixy="-0.00000074" ixz="-0.00000050" iyy="0.00010180" iyz="-0.00000089" izz="0.00008352"/>
    </inertial>

    <visual>
      <geometry>
        <mesh scale="0.001 0.001 0.001" filename="package://master_arm_display_pkg/urdf/meshes/MA_Link_J1L.stl" />
      </geometry>
      <material name="LightGrey">
        <color rgba="0.7 0.7 0.7 1.0"/>
      </material>
    </visual>
  </link>


    <link name="MA_Link_J2L">
    <inertial>
      <mass value="0.24640382"/>
      <origin rpy="0 0 0" xyz="0.01296806 0.00003277 -0.06516183"/>
      <inertia ixx="0.00013620" ixy="0.00000010" ixz="0.00002637" iyy="0.00018743" iyz="-0.00000055" izz="0.00011718"/>
    </inertial>

    <visual>
      <geometry>
        <mesh scale="0.001 0.001 0.001" filename="package://master_arm_display_pkg/urdf/meshes/MA_Link_J2L.stl" />
      </geometry>
      <material name="LightGrey">
        <color rgba="0.7 0.7 0.7 1.0"/>
      </material>
    </visual>
  </link>


      <link name="MA_Link_J3L">
    <inertial>
      <mass value="0.21684595"/>
      <origin rpy="0 0 0" xyz="0.00870155 -0.00016568 -0.18770935"/>
      <inertia ixx="0.00051437" ixy="0.00000023" ixz="0.00008538" iyy="0.00054804" iyz="-0.00000156" izz="0.00007709"/>
    </inertial>

    <visual>
      <geometry>
        <mesh scale="0.001 0.001 0.001" filename="package://master_arm_display_pkg/urdf/meshes/MA_Link_J3L.stl" />
      </geometry>
      <material name="LightGrey">
        <color rgba="0.7 0.7 0.7 1.0"/>
      </material>
    </visual>
  </link>


      <link name="MA_Link_J4L">
    <inertial>
      <mass value="0.15321181"/>
      <origin rpy="0 0 0" xyz="-0.02150470 0.00006753 -0.04223570"/>
      <inertia ixx="0.00005787" ixy="0.00000016" ixz="-0.00000159" iyy="0.00006286" iyz="-0.00000006" izz="0.00005833"/>
    </inertial>

    <visual>
      <geometry>
        <mesh scale="0.001 0.001 0.001" filename="package://master_arm_display_pkg/urdf/meshes/MA_Link_J4L.stl" />
      </geometry>
      <material name="LightGrey">
        <color rgba="0.7 0.7 0.7 1.0"/>
      </material>
    </visual>
  </link>


      <link name="MA_Link_J5L">
    <inertial>
      <mass value="0.26207359"/>
      <origin rpy="0 0 0" xyz="0.00441616 0.00530597 -0.09039280"/>
      <inertia ixx="0.00055030" ixy="0.00000602" ixz="-0.00003459" iyy="0.00056436" iyz="-0.00005946" izz="0.00009950"/>
    </inertial>

    <visual>
      <geometry>
        <mesh scale="0.001 0.001 0.001" filename="package://master_arm_display_pkg/urdf/meshes/MA_Link_J5L.stl" />
      </geometry>
      <material name="LightGrey">
        <color rgba="0.7 0.7 0.7 1.0"/>
      </material>
    </visual>
  </link>


      <link name="MA_Link_J6L">
    <inertial>
      <mass value="0.12931104"/>
      <origin rpy="0 0 0" xyz="0.08132607 -0.08060599 -0.05823234"/>
      <inertia ixx="0.00057977" ixy="0.00012522" ixz="0.00006868" iyy="0.00071017" iyz="-0.00023495" izz="0.00058411"/>
    </inertial>

    <visual>
      <geometry>
        <mesh scale="0.001 0.001 0.001" filename="package://master_arm_display_pkg/urdf/meshes/MA_Link_J6L.stl" />
      </geometry>
      <material name="LightGrey">
        <color rgba="0.7 0.7 0.7 1.0"/>
      </material>
    </visual>
  </link>


    <link name="MA_Link_J7L">
    <inertial>
      <mass value="0.30239425"/>
      <origin rpy="0 0 0" xyz="0.02315134 0.00001279 -0.08248957"/>
      <inertia ixx="0.00022759" ixy="0.00000089" ixz="0.00003619" iyy="0.00064028" iyz="0.00000001" izz="0.00063638"/>
    </inertial>

    <visual>
      <geometry>
        <mesh scale="0.001 0.001 0.001" filename="package://master_arm_display_pkg/urdf/meshes/MA_Link_J7L.stl" />
      </geometry>
      <material name="LightGrey">
        <color rgba="0.7 0.7 0.7 1.0"/>
      </material>
    </visual>
  </link>




    <!-- Joints -->
  <joint name="world_joint" type="fixed">
    <parent link="world"/>
    <child link="MA_Base"/>
    <origin rpy="0.0 0.0 0.0" xyz="0.0 0.0 0.0"/>
    <axis xyz="0 0 0"/>
  </joint>


    <!-- Joints_R -->
  <joint name="J1_Shoulder_Pitch" type="revolute">
    <parent link="MA_Base"/>
    <child link="MA_Link_J1R"/>
    <origin rpy="0.0 0.0 0.0" xyz="0.0 -0.300 0.0"/>
    <axis xyz="0.0 0.93969262 -0.34202014"/>
    <limit effort="1000.0" lower="-3.14159265" upper="3.14159265" velocity="3.14159265"/>
  </joint>

  <joint name="J2_Shoulder_Roll" type="revolute">
    <parent link="MA_Link_J1R"/>
    <child link="MA_Link_J2R"/>
    <origin rpy="0.0 0.0 0.0" xyz="0.0 0.0 0.0"/>
    <axis xyz="1 0 0"/>
    <limit effort="1000.0" lower="-2.356194488" upper="0.174532925" velocity="3.14159265"/>
  </joint>

  <joint name="J3_Shoulder_Yaw" type="revolute">
    <parent link="MA_Link_J2R"/>
    <child link="MA_Link_J3R"/>
    <origin rpy="0.0 0.0 0.0" xyz="0.0 0.0 0.0"/>
    <axis xyz="0 0 1"/>
    <limit effort="1000.0" lower="-2.705260338" upper="2.705260338" velocity="3.14159265"/>
  </joint>

    <joint name="J4_Elbow_Pitch" type="revolute">
    <parent link="MA_Link_J3R"/>
    <child link="MA_Link_J4R"/>
    <origin rpy="0.0 0.0 0.0" xyz="0.032 0.0 -0.230"/>
    <axis xyz="0 1 0"/>
    <limit effort="1000.0" lower="-3.054326190" upper="0.087266463" velocity="3.14159265"/>
  </joint>

    <joint name="J4_Wrist_Yaw1" type="revolute">
    <parent link="MA_Link_J4R"/>
    <child link="MA_Link_J5R"/>
    <origin rpy="0.0 0.0 0.0" xyz="-0.032 0.0 -0.245"/>
    <axis xyz="0 0 1"/>
    <limit effort="1000.0" lower="-2.705260338" upper="2.705260338" velocity="3.14159265"/>
  </joint>

    <joint name="J5_Wrist_Pitch" type="revolute">
    <parent link="MA_Link_J5R"/>
    <child link="MA_Link_J6R"/>
    <origin rpy="0.0 0.0 0.0" xyz="0.0 0.0 0.0"/>
    <axis xyz="0 1 0"/>
    <limit effort="1000.0" lower="-2.268928025" upper="2.0943951" velocity="3.14159265"/>
  </joint>

    <joint name="J6_Wrist_Yaw2" type="revolute">
    <parent link="MA_Link_J6R"/>
    <child link="MA_Link_J7R"/>
    <origin rpy="0.0 0.0 0.0" xyz="0.040 0.120 0.0"/>
    <axis xyz="0 0 1"/>
    <limit effort="1000.0" lower="-3.14159265" upper="3.14159265" velocity="3.14159265"/>
  </joint>


    <!-- Joints_L -->
  <joint name="J7_Shoulder_Pitch" type="revolute">
    <parent link="MA_Base"/>
    <child link="MA_Link_J1L"/>
    <origin rpy="3.14159265 0.0 0.0" xyz="0.0 0.300 0.0"/>
    <axis xyz="0.0 0.93969262 0.34202014"/>
    <limit effort="1000.0" lower="-3.14159265" upper="3.14159265" velocity="3.14159265"/>
  </joint>

  <joint name="J8_Shoulder_Roll" type="revolute">
    <parent link="MA_Link_J1L"/>
    <child link="MA_Link_J2L"/>
    <origin rpy="0.0 0.0 0.0" xyz="0.0 0.0 0.0"/>
    <axis xyz="1 0 0"/>
    <limit effort="1000.0" lower="-0.174532925" upper="2.356194488" velocity="3.14159265"/>
  </joint>

  <joint name="J9_Shoulder_Yaw" type="revolute">
    <parent link="MA_Link_J2L"/>
    <child link="MA_Link_J3L"/>
    <origin rpy="0.0 0.0 0.0" xyz="0.0 0.0 0.0"/>
    <axis xyz="0 0 1"/>
    <limit effort="1000.0" lower="-2.705260338" upper="2.705260338" velocity="3.14159265"/>
  </joint>

    <joint name="J10_Elbow" type="revolute">
    <parent link="MA_Link_J3L"/>
    <child link="MA_Link_J4L"/>
    <origin rpy="0.0 0.0 0.0" xyz="0.032 0.0 0.230"/>
    <axis xyz="0 1 0"/>
    <limit effort="1000.0" lower="-0.087266463" upper="3.054326190" velocity="3.14159265"/>
  </joint>

    <joint name="J11_Wrist_Yaw1" type="revolute">
    <parent link="MA_Link_J4L"/>
    <child link="MA_Link_J5L"/>
    <origin rpy="0.0 0.0 0.0" xyz="-0.032 0.0 0.245"/>
    <axis xyz="0 0 1"/>
    <limit effort="1000.0" lower="-2.705260338" upper="2.705260338" velocity="3.14159265"/>
  </joint>

    <joint name="J12_Wrist_Pitch" type="revolute">
    <parent link="MA_Link_J5L"/>
    <child link="MA_Link_J6L"/>
    <origin rpy="0.0 0.0 0.0" xyz="0.0 0.0 0.0"/>
    <axis xyz="0 1 0"/>
    <limit effort="1000.0" lower="-2.268928025" upper="2.0943951" velocity="3.14159265"/>
  </joint>

    <joint name="J13_Wrist_Yaw2" type="revolute">
    <parent link="MA_Link_J6L"/>
    <child link="MA_Link_J7L"/>
    <origin rpy="3.14159265 0.0 0.0" xyz="0.040 0.120 0.0"/>
    <axis xyz="0 0 1"/>
    <limit effort="1000.0" lower="-3.14159265" upper="3.14159265" velocity="3.14159265"/>
  </joint>

</robot>
